Workbook

Sheet Scenarios
B2: Scenario | C2: 2 | E2: Pelo Baixo impacto geral "Other Bets" e "Hedging" foram deixados para serem alterados no caso especificos, deixando valores justos baseados no passado nos calculos
B3: =IF(C2=2,"Base Case",IF(C2=1,"Bear Case","Bull Case")) -> Base Case
D5: Search Growth (%) | M5: g | O5: fonte | P5: k/pp | R5: λ(alavancagem
D6: 2Q26e | E6: 3Q26e | F6: 4Q26e | G6: =2027 -> 2027 | H6: =G6+1 -> 2028 | I6: =H6+1 -> 2029 | J6: 2030 | K6: 2031 | M6: =M7-1% -> 0.035 | O6: Search | P6: =AN22 -> 0.23222731 | R6: 0.4 | S6: Bull
B7: Scenario | C7: =C2 -> 2 | M7: 0.045 | O7: YouTube | P7: =AN23 -> 0.17054934 | R7: 0.25 | S7: Bear
B8: Bear | D8: =D9*(1-$P$6*$R$6) -> 0.13606636 | E8: =E9*(1-$P$6*$R$6) -> 0.13606636 | F8: =F9*(1-$P$6*$R$6) -> 0.13606636 | G8: =G9*(1-$P$6*$R$6) -> 0.18142182 | H8: =H9*(1-$P$6*$R$6) -> 0.15420854 | I8: =I9*(1-$P$6*$R$6) -> 0.12699527 | J8: =J9*(1-$P$6*$R$6) -> 0.10885309 | K8: =K9*(1-$P$6*$R$6) -> 0.090710908 | M8: =M7+0.5% -> 0.05 | O8: Subs | P8: =AN24 -> 0.28996213
B9: Base | D9: 0.15 | E9: 0.15 | F9: 0.15 | G9: 0.2 | H9: 0.17 | I9: 0.14 | J9: 0.12 | K9: 0.1 | M9: =CHOOSE($C$2,M6,M7,M8) -> 0.045 | O9: Cloud | P9: =AN25 -> 0.34561102 | R9: instensidade
B10: Bull | D10: =D9*(1+$P$6*$R$10) -> 0.16741705 | E10: =E9*(1+$P$6*$R$10) -> 0.16741705 | F10: =F9*(1+$P$6*$R$10) -> 0.16741705 | G10: =G9*(1+$P$6*$R$10) -> 0.22322273 | H10: =H9*(1+$P$6*$R$10) -> 0.18973932 | I10: =I9*(1+$P$6*$R$10) -> 0.15625591 | J10: =J9*(1+$P$6*$R$10) -> 0.13393364 | K10: =K9*(1+$P$6*$R$10) -> 0.11161137 | O10: Network | P10: =AM26 -> 0.013554432 | R10: 0.5
B11: Running | D11: =CHOOSE($C$2,D8,D9,D10) -> 0.15 | E11: =CHOOSE($C$2,E8,E9,E10) -> 0.15 | F11: =CHOOSE($C$2,F8,F9,F10) -> 0.15 | G11: =CHOOSE($C$2,G8,G9,G10) -> 0.2 | H11: =CHOOSE($C$2,H8,H9,H10) -> 0.17 | I11: =CHOOSE($C$2,I8,I9,I10) -> 0.14 | J11: =CHOOSE($C$2,J8,J9,J10) -> 0.12 | K11: =CHOOSE($C$2,K8,K9,K10) -> 0.1 | O11: ServMg | P11: =AM27 -> 0.020254053
O12: CloudMg | P12: =AM28 -> 0.067296354
D13: Youtube Ads Growth (%)
D14: 2Q26e | E14: 3Q26e | F14: 4Q26e | G14: =2027 -> 2027 | H14: =G14+1 -> 2028 | I14: =H14+1 -> 2029 | J14: 2030 | K14: 2031
B15: Scenario | C15: =C2 -> 2
B16: Bear | D16: =D17*(1-$P$7*$R$10) -> 0.08232528 | E16: =E17*(1-$P$7*$R$10) -> 0.08232528 | F16: =F17*(1-$P$7*$R$10) -> 0.08232528 | G16: =G17*(1-$P$7*$R$10) -> 0.10976704 | H16: =H17*(1-$P$7*$R$10) -> 0.10061979 | I16: =I17*(1-$P$7*$R$10) -> 0.10061979 | J16: =J17*(1-$P$7*$R$10) -> 0.091472533 | K16: =K17*(1-$P$7*$R$10) -> 0.08232528
B17: Base | D17: 0.09 | E17: 0.09 | F17: 0.09 | G17: 0.12 | H17: 0.11 | I17: 0.11 | J17: 0.1 | K17: 0.09
B18: Bull | D18: =D17*(1+$P$7*$R$10) -> 0.09767472 | E18: =E17*(1+$P$7*$R$10) -> 0.09767472 | F18: =F17*(1+$P$7*$R$10) -> 0.09767472 | G18: =G17*(1+$P$7*$R$10) -> 0.13023296 | H18: =H17*(1+$P$7*$R$10) -> 0.11938021 | I18: =I17*(1+$P$7*$R$10) -> 0.11938021 | J18: =J17*(1+$P$7*$R$10) -> 0.10852747 | K18: =K17*(1+$P$7*$R$10) -> 0.09767472
B19: Running | D19: =CHOOSE($C2,D16,D17,D18) -> 0.09 | E19: =CHOOSE($C2,E16,E17,E18) -> 0.09 | F19: =CHOOSE($C2,F16,F17,F18) -> 0.09 | G19: =CHOOSE($C2,G16,G17,G18) -> 0.12 | H19: =CHOOSE($C2,H16,H17,H18) -> 0.11 | I19: =CHOOSE($C2,I16,I17,I18) -> 0.11 | J19: =CHOOSE($C2,J16,J17,J18) -> 0.1 | K19: =CHOOSE($C2,K16,K17,K18) -> 0.09
X20: Cálculo do k (base histórica)
D21: Google Subscription Growth (%) | X21: Driver | Y21: 1Q23 | Z21: 2Q23 | AA21: 3Q23 | AB21: 4Q23 | AC21: 1Q24 | AD21: 2Q24 | AE21: 3Q24 | AF21: 4Q24 | AG21: 1Q25 | AH21: 2Q25 | AI21: 3Q25 | AJ21: 4Q25 | AK21: 1Q26 | AL21: μ (13t) | AM21: σ (8t) | AN21: k = σ/μ
D22: 2Q26e | E22: 3Q26e | F22: 4Q26e | G22: =2027 -> 2027 | H22: =G22+1 -> 2028 | I22: =H22+1 -> 2029 | J22: 2030 | K22: 2031 | X22: Search | Y22: ='Build Up'!K8/'Build Up'!F8-1 -> 0.01870362 | Z22: ='Build Up'!L8/'Build Up'!G8-1 -> 0.047654157 | AA22: ='Build Up'!M8/'Build Up'!H8-1 -> 0.11348289 | AB22: ='Build Up'!N8/'Build Up'!I8-1 -> 0.12712421 | AC22: ='Build Up'!P8/'Build Up'!K8-1 -> 0.14363587 | AD22: ='Build Up'!Q8/'Build Up'!L8-1 -> 0.13796096 | AE22: ='Build Up'!R8/'Build Up'!M8-1 -> 0.12172353 | AF22: ='Build Up'!S8/'Build Up'!N8-1 -> 0.12523948 | AG22: ='Build Up'!U8/'Build Up'!P8-1 -> 0.09849207 | AH22: ='Build Up'!V8/'Build Up'!Q8-1 -> 0.11711229 | AI22: ='Build Up'!W8/'Build Up'!R8-1 -> 0.14542877 | AJ22: ='Build Up'!X8/'Build Up'!S8-1 -> 0.16728356 | AK22: ='Build Up'!Z8/'Build Up'!U8-1 -> 0.19125478 | AL22: =AVERAGE(Y22:AK22) -> 0.11962278 | AM22: =STDEVP(AD22:AK22) -> 0.027779677 | AN22: =AM22/AL22 -> 0.23222731
B23: Scenario | C23: =C2 -> 2 | X23: YouTube | Y23: ='Build Up'!K11/'Build Up'!F11-1 -> -0.025622361 | Z23: ='Build Up'!L11/'Build Up'!G11-1 -> 0.044277929 | AA23: ='Build Up'!M11/'Build Up'!H11-1 -> 0.12459341 | AB23: ='Build Up'!N11/'Build Up'!I11-1 -> 0.15534346 | AC23: ='Build Up'!P11/'Build Up'!K11-1 -> 0.20872553 | AD23: ='Build Up'!Q11/'Build Up'!L11-1 -> 0.13020222 | AE23: ='Build Up'!R11/'Build Up'!M11-1 -> 0.12185614 | AF23: ='Build Up'!S11/'Build Up'!N11-1 -> 0.13836957 | AG23: ='Build Up'!U11/'Build Up'!P11-1 -> 0.10346106 | AH23: ='Build Up'!V11/'Build Up'!Q11-1 -> 0.1307861 | AI23: ='Build Up'!W11/'Build Up'!R11-1 -> 0.15020738 | AJ23: ='Build Up'!X11/'Build Up'!S11-1 -> 0.086890098 | AK23: ='Build Up'!Z11/'Build Up'!U11-1 -> 0.10709085 | AL23: =AVERAGE(Y23:AK23) -> 0.11355241 | AM23: =STDEVP(AD23:AK23) -> 0.019366289 | AN23: =AM23/AL23 -> 0.17054934
B24: Bear | D24: =D25*(1-$P$8*$R$10) -> 0.11970265 | E24: =E25*(1-$P$8*$R$10) -> 0.11970265 | F24: =F25*(1-$P$8*$R$10) -> 0.11970265 | G24: =G25*(1-$P$8*$R$10) -> 0.12825284 | H24: =H25*(1-$P$8*$R$10) -> 0.13680303 | I24: =I25*(1-$P$8*$R$10) -> 0.14535322 | J24: =J25*(1-$P$8*$R$10) -> 0.13680303 | K24: =K25*(1-$P$8*$R$10) -> 0.12825284 | X24: Subscriptions | Y24: ='Build Up'!K17/'Build Up'!F17-1 -> 0.088386434 | Z24: ='Build Up'!L17/'Build Up'!G17-1 -> 0.24248436 | AA24: ='Build Up'!M17/'Build Up'!H17-1 -> 0.20942712 | AB24: ='Build Up'!N17/'Build Up'!I17-1 -> 0.2271487 | AC24: ='Build Up'!P17/'Build Up'!K17-1 -> 0.17887495 | AD24: ='Build Up'!Q17/'Build Up'!L17-1 -> 0.14369934 | AE24: ='Build Up'!R17/'Build Up'!M17-1 -> 0.27785106 | AF24: ='Build Up'!S17/'Build Up'!N17-1 -> 0.077728368 | AG24: ='Build Up'!U17/'Build Up'!P17-1 -> 0.18766449 | AH24: ='Build Up'!V17/'Build Up'!Q17-1 -> 0.20307131 | AI24: ='Build Up'!W17/'Build Up'!R17-1 -> 0.20777027 | AJ24: ='Build Up'!X17/'Build Up'!S17-1 -> 0.16719677 | AK24: ='Build Up'!Z17/'Build Up'!U17-1 -> 0.19317853 | AL24: =AVERAGE(Y24:AK24) -> 0.18496013 | AM24: =STDEVP(AD24:AK24) -> 0.053631434 | AN24: =AM24/AL24 -> 0.28996213
B25: Base | D25: 0.14 | E25: 0.14 | F25: 0.14 | G25: 0.15 | H25: 0.16 | I25: 0.17 | J25: 0.16 | K25: 0.15 | X25: Cloud | Y25: ='Build Up'!K22/'Build Up'!F22-1 -> 0.28053599 | Z25: ='Build Up'!L22/'Build Up'!G22-1 -> 0.27963671 | AA25: ='Build Up'!M22/'Build Up'!H22-1 -> 0.22466511 | AB25: ='Build Up'!N22/'Build Up'!I22-1 -> 0.25659604 | AC25: ='Build Up'!P22/'Build Up'!K22-1 -> 0.28441105 | AD25: ='Build Up'!Q22/'Build Up'!L22-1 -> 0.28838252 | AE25: ='Build Up'!R22/'Build Up'!M22-1 -> 0.34978005 | AF25: ='Build Up'!S22/'Build Up'!N22-1 -> 0.30058747 | AG25: ='Build Up'!U22/'Build Up'!P22-1 -> 0.28055149 | AH25: ='Build Up'!V22/'Build Up'!Q22-1 -> 0.31671016 | AI25: ='Build Up'!W22/'Build Up'!R22-1 -> 0.33506562 | AJ25: ='Build Up'!X22/'Build Up'!S22-1 -> 0.47754078 | AK25: ='Build Up'!Z22/'Build Up'!U22-1 -> 0.63360522 | AL25: =AVERAGE(Y25:AK25) -> 0.33138986 | AM25: =STDEVP(AD25:AK25) -> 0.11453199 | AN25: =AM25/AL25 -> 0.34561102
B26: Bull | D26: =D25*(1+$P$8*$R$10) -> 0.16029735 | E26: =E25*(1+$P$8*$R$10) -> 0.16029735 | F26: =F25*(1+$P$8*$R$10) -> 0.16029735 | G26: =G25*(1+$P$8*$R$10) -> 0.17174716 | H26: =H25*(1+$P$8*$R$10) -> 0.18319697 | I26: =I25*(1+$P$8*$R$10) -> 0.19464678 | J26: =J25*(1+$P$8*$R$10) -> 0.18319697 | K26: =K25*(1+$P$8*$R$10) -> 0.17174716 | X26: Network | Y26: ='Build Up'!K14/'Build Up'!F14-1 -> -0.082945926 | Z26: ='Build Up'!L14/'Build Up'!G14-1 -> -0.049521734 | AA26: ='Build Up'!M14/'Build Up'!H14-1 -> -0.025787602 | AB26: ='Build Up'!N14/'Build Up'!I14-1 -> -0.02100295 | AC26: ='Build Up'!P14/'Build Up'!K14-1 -> -0.011072572 | AD26: ='Build Up'!Q14/'Build Up'!L14-1 -> -0.051719745 | AE26: ='Build Up'!R14/'Build Up'!M14-1 -> -0.015777807 | AF26: ='Build Up'!S14/'Build Up'!N14-1 -> -0.041340243 | AG26: ='Build Up'!U14/'Build Up'!P14-1 -> -0.02117901 | AH26: ='Build Up'!V14/'Build Up'!Q14-1 -> -0.012090274 | AI26: ='Build Up'!W14/'Build Up'!R14-1 -> -0.025702173 | AJ26: ='Build Up'!X14/'Build Up'!S14-1 -> -0.015841086 | AK26: ='Build Up'!Z14/'Build Up'!U14-1 -> -0.039277839 | AL26: =AVERAGE(Y26:AK26) -> -0.031789151 | AM26: =STDEVP(AD26:AK26) -> 0.013554432
B27: Running | D27: =CHOOSE($C2,D24,D25,D26) -> 0.14 | E27: =CHOOSE($C2,E24,E25,E26) -> 0.14 | F27: =CHOOSE($C2,F24,F25,F26) -> 0.14 | G27: =CHOOSE($C2,G24,G25,G26) -> 0.15 | H27: =CHOOSE($C2,H24,H25,H26) -> 0.16 | I27: =CHOOSE($C2,I24,I25,I26) -> 0.17 | J27: =CHOOSE($C2,J24,J25,J26) -> 0.16 | K27: =CHOOSE($C2,K24,K25,K26) -> 0.15 | X27: Margem Services | Y27: ='Build Up'!K36 -> 0.35081745 | Z27: ='Build Up'!L36 -> 0.35383571 | AA27: ='Build Up'!M36 -> 0.35208719 | AB27: ='Build Up'!N36 -> 0.35027716 | AC27: ='Build Up'!P36 -> 0.39627546 | AD27: ='Build Up'!Q36 -> 0.40139054 | AE27: ='Build Up'!R36 -> 0.40329369 | AF27: ='Build Up'!S36 -> 0.39046781 | AG27: ='Build Up'!U36 -> 0.4229913 | AH27: ='Build Up'!V36 -> 0.40055486 | AI27: ='Build Up'!W36 -> 0.38513762 | AJ27: ='Build Up'!X36 -> 0.41864347 | AK27: ='Build Up'!Z36 -> 0.45281524 | AL27: =AVERAGE(Y27:AK27) -> 0.39066058 | AM27: =STDEVP(AD27:AK27) -> 0.020254053
X28: Margem Cloud | Y28: ='Build Up'!K39 -> 0.025623826 | Z28: ='Build Up'!L39 -> 0.04918441 | AA28: ='Build Up'!M39 -> 0.031625253 | AB28: ='Build Up'!N39 -> 0.093994778 | AC28: ='Build Up'!P39 -> 0.094004596 | AD28: ='Build Up'!Q39 -> 0.11326955 | AE28: ='Build Up'!R39 -> 0.17149652 | AF28: ='Build Up'!S39 -> 0.17507319 | AG28: ='Build Up'!U39 -> 0.17756933 | AH28: ='Build Up'!V39 -> 0.20742807 | AI28: ='Build Up'!W39 -> 0.23711816 | AJ28: ='Build Up'!X39 -> 0.30078125 | AK28: ='Build Up'!Z39 -> 0.32943879 | AL28: =AVERAGE(Y28:AK28) -> 0.15435444 | AM28: =STDEVP(AD28:AK28) -> 0.067296354
D29: Google Cloud Growth (%)
D30: 2Q26e | E30: 3Q26e | F30: 4Q26e | G30: =2027 -> 2027 | H30: =G30+1 -> 2028 | I30: =H30+1 -> 2029 | J30: 2030 | K30: 2031
B31: Scenario | C31: =C2 -> 2
B32: Bear | D32: =D33*(1-$P$9*$R$10) -> 0.24815835 | E32: =E33*(1-$P$9*$R$10) -> 0.24815835 | F32: =F33*(1-$P$9*$R$10) -> 0.24815835 | G32: =G33*(1-$P$9*$R$10) -> 0.41359725 | H32: =H33*(1-$P$9*$R$10) -> 0.26470224 | I32: =I33*(1-$P$9*$R$10) -> 0.1654389 | J32: =J33*(1-$P$9*$R$10) -> 0.12407917 | K32: =K33*(1-$P$9*$R$10) -> 0.082719449
B33: Base | D33: 0.3 | E33: 0.3 | F33: 0.3 | G33: 0.5 | H33: 0.32 | I33: 0.2 | J33: 0.15 | K33: 0.1
B34: Bull | D34: =D33*(1+$P$9*$R$10) -> 0.35184165 | E34: =E33*(1+$P$9*$R$10) -> 0.35184165 | F34: =F33*(1+$P$9*$R$10) -> 0.35184165 | G34: =G33*(1+$P$9*$R$10) -> 0.58640275 | H34: =H33*(1+$P$9*$R$10) -> 0.37529776 | I34: =I33*(1+$P$9*$R$10) -> 0.2345611 | J34: =J33*(1+$P$9*$R$10) -> 0.17592083 | K34: =K33*(1+$P$9*$R$10) -> 0.11728055
B35: Running | D35: =CHOOSE($C2,D32,D33,D34) -> 0.3 | E35: =CHOOSE($C2,E32,E33,E34) -> 0.3 | F35: =CHOOSE($C2,F32,F33,F34) -> 0.3 | G35: =CHOOSE($C2,G32,G33,G34) -> 0.5 | H35: =CHOOSE($C2,H32,H33,H34) -> 0.32 | I35: =CHOOSE($C2,I32,I33,I34) -> 0.2 | J35: =CHOOSE($C2,J32,J33,J34) -> 0.15 | K35: =CHOOSE($C2,K32,K33,K34) -> 0.1
D37: Google Cloud Margin (%)
D38: 2Q26e | E38: 3Q26e | F38: 4Q26e | G38: =2027 -> 2027 | H38: =G38+1 -> 2028 | I38: =H38+1 -> 2029 | J38: 2030 | K38: 2031
B39: Scenario | C39: =C2 -> 2
B40: Bear | D40: =D41-$P$12*$R$10-(D33*$P$9*$R$10*$R$7) -> 0.30339141 | E40: =E41-$P$12*$R$10-(E33*$P$9*$R$10*$R$7) -> 0.29339141 | F40: =F41-$P$12*$R$10-(F33*$P$9*$R$10*$R$7) -> 0.29339141 | G40: =G41-$P$12*$R$10-(G33*$P$9*$R$10*$R$7) -> 0.28475113 | H40: =H41-$P$12*$R$10-(H33*$P$9*$R$10*$R$7) -> 0.30252738 | I40: =I41-$P$12*$R$10-(I33*$P$9*$R$10*$R$7) -> 0.31771155 | J40: =J41-$P$12*$R$10-(J33*$P$9*$R$10*$R$7) -> 0.32987162 | K40: =K41-$P$12*$R$10-(K33*$P$9*$R$10*$R$7) -> 0.34203169
B41: Base | D41: 0.35 | E41: 0.34 | F41: 0.34 | G41: 0.34 | H41: 0.35 | I41: 0.36 | J41: 0.37 | K41: 0.38
B42: Bull | D42: =D41+$P$12*$R$10+(D33*$P$9*$R$10*$R$6) -> 0.40438484 | E42: =E41+$P$12*$R$10+(E33*$P$9*$R$10*$R$6) -> 0.39438484 | F42: =F41+$P$12*$R$10+(F33*$P$9*$R$10*$R$6) -> 0.39438484 | G42: =G41+$P$12*$R$10+(G33*$P$9*$R$10*$R$6) -> 0.40820928 | H42: =H41+$P$12*$R$10+(H33*$P$9*$R$10*$R$6) -> 0.40576728 | I42: =I41+$P$12*$R$10+(I33*$P$9*$R$10*$R$6) -> 0.40747262 | J42: =J41+$P$12*$R$10+(J33*$P$9*$R$10*$R$6) -> 0.41401651 | K42: =K41+$P$12*$R$10+(K33*$P$9*$R$10*$R$6) -> 0.4205604
B43: Running | D43: =CHOOSE($C7,D40,D41,D42) -> 0.35 | E43: =CHOOSE($C7,E40,E41,E42) -> 0.34 | F43: =CHOOSE($C7,F40,F41,F42) -> 0.34 | G43: =CHOOSE($C7,G40,G41,G42) -> 0.34 | H43: =CHOOSE($C7,H40,H41,H42) -> 0.35 | I43: =CHOOSE($C7,I40,I41,I42) -> 0.36 | J43: =CHOOSE($C7,J40,J41,J42) -> 0.37 | K43: =CHOOSE($C7,K40,K41,K42) -> 0.38
...

Sheet Income Statement
O1: Hardcode
O2: Formula
O3: Assumption
A5: Income Statement (Mn USD) | D5: 2020 | E5: 2021 | F5: 1Q22 | G5: 2Q22 | H5: 3Q22 | I5: 4Q22 | J5: 2022 | K5: 1Q23 | L5: 2Q23 | M5: 3Q23 | N5: 4Q23 | O5: 2023 | P5: 1Q24 | Q5: 2Q24 | R5: 3Q24 | S5: 4Q24 | T5: 2024 | U5: 1Q25 | V5: 2Q25 | W5: 3Q25 | X5: 4Q25 | Y5: 2025 | Z5: 1Q26 | AA5: 2Q26 | AB5: 3Q26 | AC5: 4Q26 | AD5: 2026 | AE5: 2027 | AF5: 2028 | AG5: 2029 | AH5: 2030 | AI5: 2031
A6: Revenues | D6: 182527 | E6: 257637 | F6: 68011 | G6: 69685 | H6: 69092 | I6: =J6-SUM(F6:H6) -> 76048 | J6: 282836 | K6: 69787 | L6: 74604 | M6: 76693 | N6: =O6-SUM(K6:M6) -> 86310 | O6: 307394 | P6: 80539 | Q6: 84742 | R6: 88268 | S6: =T6-SUM(P6:R6) -> 96469 | T6: 350018 | U6: 90234 | V6: 96428 | W6: 102346 | X6: =Y6-SUM(U6:W6) -> 113828 | Y6: 402836 | Z6: 109896 | AA6: ='Build Up'!AA6 -> 119510.96 | AB6: ='Build Up'!AB6 -> 134833.52 | AC6: ='Build Up'!AC6 -> 153408.59 | AD6: ='Build Up'!AD6 -> 517649.07 | AE6: ='Build Up'!AE6 -> 632924.59 | AF6: ='Build Up'!AF6 -> 749787.04 | AG6: ='Build Up'!AG6 -> 860924.23 | AH6: ='Build Up'!AH6 -> 969031.63 | AI6: ='Build Up'!AI6 -> 1067907.9
A7: y/y(%) | E7: =E6/D6-1 -> 0.41150076 | J7: =J6/E6-1 -> 0.097808156 | K7: =K6/F6-1 -> 0.026113423 | L7: =L6/G6-1 -> 0.070589079 | M7: =M6/H6-1 -> 0.11001274 | N7: =N6/I6-1 -> 0.13494109 | O7: =O6/J6-1 -> 0.086827702 | P7: =P6/K6-1 -> 0.15406881 | Q7: =Q6/L6-1 -> 0.13589084 | ... AD7: =AD6/Y6-1 -> 0.28501194 | AE7: =AE6/AD6-1 -> 0.22269048 | AF7: =AF6/AE6-1 -> 0.18463882 | AG7: =AG6/AF6-1 -> 0.14822501 | AH7: =AH6/AG6-1 -> 0.12557132 | AI7: =AI6/AH6-1 -> 0.10203615
A8: (-)Cost of revenues | D8: 84732 | E8: 110939 | F8: 29599 | G8: 30104 | H8: 31158 | I8: =J8-SUM(F8:H8) -> 35342 | J8: 126203 | K8: 30612 | L8: 31916 | M8: 33229 | N8: =O8-SUM(K8:M8) -> 37575 | O8: 133332 | P8: 33712 | Q8: 35507 | R8: 36474 | S8: =T8-SUM(P8:R8) -> 40613 | T8: 146306 | U8: 36361 | V8: 39039 | W8: 41369 | X8: =Y8-SUM(U8:W8) -> 45766 | Y8: 162535 | Z8: 41271 | AA8: ='Build Up'!AA50 -> 43331.862 | AB8: ='Build Up'!AB50 -> 48966.555 | AC8: ='Build Up'!AC50 -> 55687.164 | AD8: ='Build Up'!AD50 -> 189263.18 | AE8: ='Build Up'!AE50 -> 230709.54 | AF8: ='Build Up'!AF50 -> 269268.43 | AG8: ='Build Up'!AG50 -> 304178.06 | AH8: ='Build Up'!AH50 -> 341036.4 | AI8: ='Build Up'!AI50 -> 374216.09
A10: Gross Profit | D10: =D6-D8 -> 97795 | E10: =E6-E8 -> 146698 | F10: =F6-F8 -> 38412 | G10: =G6-G8 -> 39581 | H10: =H6-H8 -> 37934 | I10: =I6-I8 -> 40706 | J10: =J6-J8 -> 156633 | K10: =K6-K8 -> 39175 | ... AI10: =AI6-AI8 -> 693691.8
A12: (-)SG&A | D12: =D13+D14+D15 -> 56571 | E12: =E13+E14+E15 -> 67984 | F12: =F13+F14+F15 -> 18318 | G12: =G13+G14+G15 -> 20128 | H12: =H13+H14+H15 -> 20799 | I12: =I13+I14+I15 -> 22546 | J12: =J13+J14+J15 -> 81791 | K12: =K13+K14+K15 -> 21760 | ... Z12: =Z13+Z14+Z15 -> 28929 | AA12: ='Build Up'!AA53 -> 30361.781 | AB12: ='Build Up'!AB53 -> 34309.899 | AC12: ='Build Up'!AC53 -> 39018.897 | AD12: ='Build Up'!AD53 -> 132619.58 | AE12: ='Build Up'!AE53 -> 159299.45 | AF12: ='Build Up'!AF53 -> 185923.44 | AG12: ='Build Up'!AG53 -> 210027.71 | AH12: ='Build Up'!AH53 -> 235477.51 | AI12: ='Build Up'!AI53 -> 258387.3
B13: Research and development | D13: 27573 | E13: 31562 | F13: 9119 | G13: 9841 | H13: 10273 | I13: =J13-SUM(F13:H13) -> 10267 | J13: 39500 | K13: 11468 | L13: 10588 | M13: 11258 | N13: =O13-SUM(K13:M13) -> 12113 | O13: 45427 | P13: 11903 | Q13: 11860 | R13: 12447 | S13: =T13-SUM(P13:R13) -> 13116 | T13: 49326 | U13: 13556 | V13: 13808 | W13: 15151 | X13: =Y13-SUM(U13:W13) -> 18572 | Y13: 61087 | Z13: 17032 | AA13: =AA$12*Z13/SUM(Z$13:Z$15) -> 17875.552 | AB13: =AB$12*AA13/SUM(AA$13:AA$15) -> 20200.014 | AC13: =AC$12*AB13/SUM(AB$13:AB$15) -> 22972.445 | AD13: =AD$12*AC13/SUM(AC$13:AC$15) -> 78080.011 | AE13: =AE$12*AD13/SUM(AD$13:AD$15) -> 93787.831 | AF13: =AF$12*AE13/SUM(AE$13:AE$15) -> 109462.76 | AG13: =AG$12*AF13/SUM(AF$13:AF$15) -> 123654.19 | AH13: =AH$12*AG13/SUM(AG$13:AG$15) -> 138637.8 | AI13: =AI$12*AH13/SUM(AH$13:AH$15) -> 152125.98
B14: Sales and marketing | D14: 17946 | E14: 22912 | F14: 5825 | G14: 6630 | H14: 6929 | I14: =J14-SUM(F14:H14) -> 7183 | J14: 26567 | K14: 6533 | L14: 6781 | M14: 6884 | N14: =O14-SUM(K14:M14) -> 7719 | O14: 27917 | P14: 6426 | Q14: 6792 | R14: 7227 | S14: =T14-SUM(P14:R14) -> 7363 | T14: 27808 | U14: 6172 | V14: 7101 | W14: 7205 | X14: =Y14-SUM(U14:W14) -> 8215 | Y14: 28693 | Z14: 7606 | AA14: =AA$12*Z14/SUM(Z$13:Z$15) -> 7982.7061 | AB14: =AB$12*AA14/SUM(AA$13:AA$15) -> 9020.7437 | AC14: =AC$12*AB14/SUM(AB$13:AB$15) -> 10258.831 | AD14: =AD$12*AC14/SUM(AC$13:AC$15) -> 34868.281 | AE14: =AE$12*AD14/SUM(AD$13:AD$15) -> 41882.941 | AF14: =AF$12*AE14/SUM(AE$13:AE$15) -> 48882.91 | AG14: =AG$12*AF14/SUM(AF$13:AF$15) -> 55220.393 | AH14: =AH$12*AG14/SUM(AG$13:AG$15) -> 61911.645 | AI14: =AI$12*AH14/SUM(AH$13:AH$15) -> 67935.076
B15: General and administrative | D15: 11052 | E15: 13510 | F15: 3374 | G15: 3657 | H15: 3597 | I15: =J15-SUM(F15:H15) -> 5096 | J15: 15724 | K15: 3759 | L15: 3481 | M15: 3979 | N15: =O15-SUM(K15:M15) -> 5206 | O15: 16425 | P15: 3026 | Q15: 3158 | R15: 3599 | S15: =T15-SUM(P15:R15) -> 4405 | T15: 14188 | U15: 3539 | V15: 5209 | W15: 7393 | X15: =Y15-SUM(U15:W15) -> 5341 | Y15: 21482 | Z15: 4291 | AA15: =AA$12*Z15/SUM(Z$13:Z$15) -> 4503.5224 | AB15: =AB$12*AA15/SUM(AA$13:AA$15) -> 5089.1416 | AC15: =AC$12*AB15/SUM(AB$13:AB$15) -> 5787.621 | AD15: =AD$12*AC15/SUM(AC$13:AC$15) -> 19671.285 | AE15: =AE$12*AD15/SUM(AD$13:AD$15) -> 23628.674 | AF15: =AF$12*AE15/SUM(AE$13:AE$15) -> 27577.776 | AG15: =AG$12*AF15/SUM(AF$13:AF$15) -> 31153.13 | AH15: =AH$12*AG15/SUM(AG$13:AG$15) -> 34928.066 | AI15: =AI$12*AH15/SUM(AH$13:AH$15) -> 38326.244
A17: EBIT | D17: 41224 | E17: 78714 | F17: =F10-F12 -> 20094 | G17: =G10-G12 -> 19453 | H17: =H10-H12 -> 17135 | I17: =I10-I12 -> 18160 | J17: 74842 | K17: =K10-K12 -> 17415 | L17: =L10-L12 -> 21838 | M17: =M10-M12 -> 21343 | N17: =N10-N12 -> 23697 | O17: 84293 | P17: =P10-P12 -> 25472 | Q17: =Q10-Q12 -> 27425 | R17: =R10-R12 -> 28521 | S17: =S10-S12 -> 30972 | T17: 112390 | U17: =U10-U12 -> 30606 | V17: =V10-V12 -> 31271 | W17: =W10-W12 -> 31228 | X17: =X10-X12 -> 35934 | Y17: 129039 | Z17: =Z10-Z12 -> 39696 | AA17: ='Build Up'!AA32 -> 45817.322 | AB17: ='Build Up'!AB32 -> 51557.065 | AC17: ='Build Up'!AC32 -> 58702.525 | AD17: ='Build Up'!AD32 -> 195772.91 | AE17: ='Build Up'!AE32 -> 240561.42 | AF17: ='Build Up'!AF32 -> 291847.53 | AG17: ='Build Up'!AG32 -> 343614.6 | AH17: ='Build Up'!AH32 -> 389037.75 | AI17: ='Build Up'!AI32 -> 431485.97
A19: (+/-)Financial Result | D19: 6858 | E19: 12020 | F19: -1160 | G19: -439 | H19: -902 | I19: =J19-SUM(F19:H19) -> -1013 | J19: -3514 | K19: 790 | L19: 65 | M19: -146 | N19: =O19-SUM(K19:M19) -> 715 | O19: 1424 | P19: 2843 | Q19: 126 | R19: 3185 | S19: =T19-SUM(P19:R19) -> 1271 | T19: 7425 | U19: 11183 | V19: 2662 | W19: 12759 | X19: =Y19-SUM(U19:W19) -> 3183 | Y19: 29787 | Z19: 37716 | AA19: =SUM(AA20:AA23) -> 3464.8552 | AB19: =SUM(AB20:AB23) -> 2228.0046 | AC19: =SUM(AC20:AC23) -> 7130.4042 | AD19: =SUM(AD20:AD23) -> 50539.264 | AE19: =SUM(AE20:AE23) -> 2524.012 | AF19: =SUM(AF20:AF23) -> -440.3219 | AG19: =SUM(AG20:AG23) -> 10855.905 | AH19: =SUM(AH20:AH23) -> 3572.9113 | AI19: =SUM(AI20:AI23) -> 822.46911
B20: (-) Interest Expense | D20: -135 | E20: -346 | F20: -83 | G20: -83 | H20: -101 | I20: =J20-SUM(F20:H20) -> -90 | J20: -357 | K20: -80 | L20: -43 | M20: -116 | N20: =O20-SUM(K20:M20) -> -69 | O20: -308 | P20: -94 | Q20: -67 | R20: -54 | S20: =T20-SUM(P20:R20) -> -53 | T20: -268 | U20: -34 | V20: -261 | W20: -143 | X20: =Y20-SUM(U20:W20) -> -298 | Y20: -736 | Z20: -533 | AA20: ='Debt Schedule'!W15 -> -796.30662 | AB20: ='Debt Schedule'!X15 -> -836.12195 | AC20: ='Debt Schedule'!Y15 -> -877.92805 | AD20: ='Debt Schedule'!Z15 -> -3043.3566 | AE20: ='Debt Schedule'!AA15 -> -3919.9547 | AF20: ='Debt Schedule'!AB15 -> -4233.5511 | AG20: ='Debt Schedule'!AC15 -> -4487.5641 | AH20: ='Debt Schedule'!AD15 -> -4667.0667 | AI20: ='Debt Schedule'!AE15 -> -4760.408
B21: (+) Interest Income | D21: 1865 | E21: 1499 | F21: 414 | G21: 486 | H21: 615 | I21: =J21-SUM(F21:H21) -> 659 | J21: 2174 | K21: 797 | L21: 892 | M21: 1066 | N21: =O21-SUM(K21:M21) -> 930 | O21: 3685 | P21: 1061 | Q21: 1090 | R21: 1243 | S21: =T21-SUM(P21:R21) -> 1088 | T21: 4482 | U21: 1001 | V21: 1050 | W21: 1076 | X21: =Y21-SUM(U21:W21) -> 1210 | Y21: 4337 | Z21: 1381 | AA21: ='Debt Schedule'!W18 -> 2216.1618 | AB21: ='Debt Schedule'!X18 -> 2143.1266 | AC21: ='Debt Schedule'!Y18 -> 1948.3322 | AD21: ='Debt Schedule'!Z18 -> 7688.6207 | AE21: ='Debt Schedule'!AA18 -> 4958.2167 | AF21: ='Debt Schedule'!AB18 -> 2585.2292 | AG21: ='Debt Schedule'!AC18 -> 760.21916 | AH21: ='Debt Schedule'!AD18 -> 2188.478 | AI21: ='Debt Schedule'!AE18 -> 4042.3771
B22: (+/-) Currency Exchange | D22: -344 | E22: -240 | F22: -73 | G22: -260 | H22: -136 | I22: =J22-SUM(F22:H22) -> -185 | J22: -654 | K22: -210 | L22: -268 | M22: -311 | N22: =O22-SUM(K22:M22) -> -449 | O22: -1238 | P22: -238 | Q22: -173 | R22: 23 | S22: =T22-SUM(P22:R22) -> -21 | T22: -409 | U22: -106 | V22: -69 | W22: -143 | X22: =Y22-SUM(U22:W22) -> -64 | Y22: -382 | Z22: 146 | AA22: =MEDIAN(Z22,U22:X22,P22:S22) -> -69 | AB22: =MEDIAN(Y22,T22,O22,J22) -> -531.5 | AC22: =MEDIAN(Z22,U22,P22,K22) -> -158 | AD22: =SUM(Z22:AC22) -> -612.5 | AE22: =MEDIAN(AB22,W22,R22,M22) -> -227 | AF22: =MEDIAN(AC22,X22,S22,N22) -> -111 | AG22: =MEDIAN(AD22,Y22,T22,O22) -> -510.75 | AH22: =MEDIAN(AE22,Z22,U22,P22) -> -166.5 | AI22: =MEDIAN(AF22,AA22,V22,Q22) -> -90
B23: (+/-) Others | D23: =D19-D20-D21-D22 -> 5472 | E23: =E19-E20-E21-E22 -> 11107 | F23: =F19-F20-F21-F22 -> -1418 | G23: =G19-G20-G21-G22 -> -582 | H23: =H19-H20-H21-H22 -> -1280 | I23: =I19-I20-I21-I22 -> -1397 | J23: =J19-J20-J21-J22 -> -4677 | K23: =K19-K20-K21-K22 -> 283 | ... Z23: =Z19-Z20-Z21-Z22 -> 36722 | AA23: =MEDIAN(Z23,U23:X23,P23:S23) -> 2114 | AB23: =MEDIAN(Y23,T23,O23,J23) -> 1452.5 | AC23: =MEDIAN(Z23,U23,P23,K23) -> 6218 | AD23: =SUM(Z23:AC23) -> 46506.5 | AE23: =MEDIAN(AB23,W23,R23,M23) -> 1712.75 | AF23: =MEDIAN(AC23,X23,S23,N23) -> 1319 | AG23: =MEDIAN(AD23,Y23,T23,O23) -> 15094 | AH23: =MEDIAN(AE23,Z23,U23,P23) -> 6218 | AI23: =MEDIAN(AF23,AA23,V23,Q23) -> 1630.5
A25: EBT | D25: 48082 | E25: 90734 | F25: =F17+F19 -> 18934 | G25: =G17+G19 -> 19014 | H25: =H17+H19 -> 16233 | I25: =I17+I19 -> 17147 | J25: 71328 | K25: =K17+K19 -> 18205 | L25: =L17+L19 -> 21903 | M25: =M17+M19 -> 21197 | N25: =N17+N19 -> 24412 | O25: 85717 | P25: =P17+P19 -> 28315 | Q25: =Q17+Q19 -> 27551 | R25: =R17+R19 -> 31706 | S25: =S17+S19 -> 32243 | T25: 119815 | U25: =U17+U19 -> 41789 | V25: =V17+V19 -> 33933 | W25: =W17+W19 -> 43987 | X25: =X17+X19 -> 39117 | Y25: 158826 | Z25: =Z17+Z19 -> 77412 | AA25: =AA17+AA19 -> 49282.177 | AB25: =AB17+AB19 -> 53785.07 | AC25: =AC17+AC19 -> 65832.929 | AD25: =AD17+AD19 -> 246312.18 | AE25: =AE17+AE19 -> 243085.44 | AF25: =AF17+AF19 -> 291407.21 | AG25: =AG17+AG19 -> 354470.51 | ... AI25: =AI17+AI19 -> 432308.43
A27: Taxes | D27: 7813 | E27: 14701 | F27: 2498 | G27: 3012 | H27: 2323 | I27: =J27-SUM(F27:H27) -> 3523 | J27: 11356 | K27: 3154 | L27: 3535 | M27: 1508 | N27: =O27-SUM(K27:M27) -> 3725 | O27: 11922 | P27: 4653 | Q27: 3932 | R27: 5405 | S27: =T27-SUM(P27:R27) -> 5707 | T27: 19697 | U27: 7249 | V27: 5737 | W27: 9008 | X27: =Y27-SUM(U27:W27) -> 4662 | Y27: 26656 | Z27: 14834 | AA27: =AA28*AA25 -> 9443.6498 | AB27: =AB28*AB25 -> 10306.512 | AC27: =AC28*AC25 -> 12615.172 | AD27: =AD28*AD25 -> 47199.334 | AE27: =AE28*AE25 -> 46581.013 | AF27: =AF28*AF25 -> 55840.625 | AG27: =AG28*AG25 -> 67925.07 | AH27: =AH28*AH25 -> 75233.641 | AI27: =AI28*AI25 -> 82840.688
B28: Effective Tax Rate | D28: =D27/D25 -> 0.16249324 | E28: =E27/E25 -> 0.16202306 | F28: =F27/F25 -> 0.13193197 | G28: =G27/G25 -> 0.15840959 | H28: =H27/H25 -> 0.14310355 | I28: =I27/I25 -> 0.20545868 | J28: =J27/J25 -> 0.15920817 | K28: =K27/K25 -> 0.17324911 | ... Z28: =Z27/Z25 -> 0.19162404 | AA28: =Z28 -> 0.19162404 | AB28: =AA28 -> 0.19162404 | AC28: =AB28 -> 0.19162404 | AD28: =AC28 -> 0.19162404 | AE28: =AD28 -> 0.19162404 | AF28: =AE28 -> 0.19162404 | AG28: =AF28 -> 0.19162404 | AH28: =AG28 -> 0.19162404 | AI28: =AH28 -> 0.19162404
A29: Net Income | D29: 40269 | E29: 76033 | F29: =F25-F27 -> 16436 | G29: =G25-G27 -> 16002 | H29: =H25-H27 -> 13910 | I29: =I25-I27 -> 13624 | J29: 59972 | K29: =K25-K27 -> 15051 | L29: =L25-L27 -> 18368 | M29: =M25-M27 -> 19689 | N29: =N25-N27 -> 20687 | O29: 73795 | P29: =P25-P27 -> 23662 | Q29: =Q25-Q27 -> 23619 | R29: =R25-R27 -> 26301 | S29: =S25-S27 -> 26536 | T29: 100118 | U29: =U25-U27 -> 34540 | V29: =V25-V27 -> 28196 | W29: =W25-W27 -> 34979 | X29: =X25-X27 -> 34455 | Y29: 132170 | Z29: =Z25-Z27 -> 62578 | AA29: =AA25-AA27 -> 39838.528 | AB29: =AB25-AB27 -> 43478.558 | AC29: =AC25-AC27 -> 53217.758 | AD29: =AD25-AD27 -> 199112.84 | AE29: =AE25-AE27 -> 196504.42 | AF29: =AF25-AF27 -> 235566.58 | AG29: =AG25-AG27 -> 286545.44 | ... AI29: =AI25-AI27 -> 349467.75
B30: Net Margin(%) | D30: =D29/D6 -> 0.22061942 | E30: =E29/E6 -> 0.29511677 | F30: =F29/F6 -> 0.24166679 | G30: =G29/G6 -> 0.22963335 | H30: =H29/H6 -> 0.20132577 | I30: =I29/I6 -> 0.17915001 | J30: =J29/J6 -> 0.21203807 | K30: =K29/K6 -> 0.21567054 | ... Z30: =Z29/Z6 -> 0.56942928
A32: Payout | D32: =-('CFS - Estimates'!D24+'CFS - Estimates'!D23) -> 31149 | E32: =-('CFS - Estimates'!E24+'CFS - Estimates'!E23) -> 50274 | J32: =-('CFS - Estimates'!F24+'CFS - Estimates'!F23) -> 59296 | O32: =-('CFS - Estimates'!K24+'CFS - Estimates'!K23) -> 61504 | T32: =-('CFS - Estimates'!P24+'CFS - Estimates'!P23) -> 69585 | Y32: =-('CFS - Estimates'!U24+'CFS - Estimates'!U23) -> 55758 | AA32: =AA29*AA33 -> 11951.558 | AB32: =AB29*AB33 -> 13043.567 | AC32: =AC29*AC33 -> 15965.327 | AD32: =AD29*AD33 -> 59733.853 | AE32: =AE29*AE33 -> 68776.548 | AF32: =AF29*AF33 -> 94226.632 | AG32: =AG29*AG33 -> 143272.72 | AH32: =AH29*AH33 -> 174557.36 | AI32: =AI29*AI33 -> 235890.73
D33: =D32/D29 -> 0.77352306 | E33: =E32/E29 -> 0.66121289 | J33: =J32/J29 -> 0.98872807 | O33: =O32/O29 -> 0.833444 | T33: =T32/T29 -> 0.69502986 | Y33: =Y32/Y29 -> 0.42186578 | AA33: 0.3 | AB33: =AA33 -> 0.3 | AC33: =AB33 -> 0.3 | AD33: =AC33 -> 0.3 | AE33: =35% -> 0.35 | AF33: 0.4 | AG33: 0.5 | AH33: 0.55 | AI33: 0.675
A35: Retained Profits | D35: =D29-D32 -> 9120 | E35: =E29-E32 -> 25759 | J35: =J29-J32 -> 676 | O35: =O29-O32 -> 12291 | T35: =T29-T32 -> 30533 | Y35: =Y29-Y32 -> 76412 | AA35: =AA29-AA32 -> 27886.969 | AB35: =AB29-AB32 -> 30434.99 | AC35: =AC29-AC32 -> 37252.43 | AD35: =AD29-AD32 -> 139378.99 | AE35: =AE29-AE32 -> 127727.88 | AF35: =AF29-AF32 -> 141339.95 | AG35: =AG29-AG32 -> 143272.72 | AH35: =AH29-AH32 -> 142819.66 | AI35: =AI29-AI32 -> 113577.02
A37: Dividens | D37: ='CFS - Estimates'!D23 -> 0 | E37: ='CFS - Estimates'!E23 -> 0 | F37: ='CFS - Estimates'!F23 -> 0 | G37: ='CFS - Estimates'!G23 -> 0 | H37: ='CFS - Estimates'!H23 -> 0 | I37: ='CFS - Estimates'!I23 -> 0 | J37: ='CFS - Estimates'!J23 -> 0 | K37: ='CFS - Estimates'!G23 -> 0 | L37: ='CFS - Estimates'!H23 -> 0 | M37: ='CFS - Estimates'!I23 -> 0 | N37: ='CFS - Estimates'!J23 -> 0 | O37: ='CFS - Estimates'!K23 -> 0 | P37: ='CFS - Estimates'!L23 -> 0 | Q37: ='CFS - Estimates'!M23 -> -2466 | R37: ='CFS - Estimates'!N23 -> -2455 | ... Z37: ='CFS - Estimates'!V23 -> -2542 | AA37: =AA32*AA38 -> 2390.3117 | AB37: =AB32*AB38 -> 2608.7135 | AC37: =AC32*AC38 -> 3193.0655 | AD37: =AD32*AD38 -> 11946.771 | AE37: =AE32*AE38 -> 13755.31 | AF37: =AF32*AF38 -> 18845.326 | AG37: =AG32*AG38 -> 28654.544 | AH37: =AH32*AH38 -> 34911.473 | AI37: =AI32*AI38 -> 47178.146
B38: As % of Payout | D38: 0 | E38: 0 | F38: 0 | G38: 0 | H38: 0 | I38: 0 | J38: 0 | K38: 0 | L38: 0 | M38: 0 | N38: 0 | O38: 0 | P38: 0 | Q38: =Q37/(Q40+Q37) -> 0.13586777 | R38: =R37/(R40+R37) -> 0.13834103 | S38: =S37/(S40+S37) -> 0.13571945 | T38: =-T37/T32 -> 0.10581303 | U38: =U37/(U40+U37) -> 0.13906982 | V38: =V37/(V40+V37) -> 0.15715963 | W38: =W37/(W40+W37) -> 0.18062678 | X38: =X37/(X40+X37) -> 0.31561917 | Y38: =-Y37/Y32 -> 0.18022526 | Z38: =Z37/(Z40+Z37) -> 1 | AA38: 0.2 | AB38: 0.2 | AC38: 0.2 | AD38: 0.2 | AE38: 0.2 | AF38: 0.2 | AG38: 0.2 | AH38: 0.2 | AI38: 0.2
A40: Repurchase of Stock | D40: ='CFS - Estimates'!D24 -> -31149 | E40: ='CFS - Estimates'!E24 -> -50274 | J40: ='CFS - Estimates'!F24 -> -59296 | K40: ='CFS - Estimates'!G24 -> -14557 | L40: ='CFS - Estimates'!H24 -> -14969 | M40: ='CFS - Estimates'!I24 -> -15787 | N40: ='CFS - Estimates'!J24 -> -16191 | O40: ='CFS - Estimates'!K24 -> -61504 | P40: ='CFS - Estimates'!L24 -> -15696 | Q40: ='CFS - Estimates'!M24 -> -15684 | ... Z40: ='CFS - Estimates'!V24 -> 0 | AA40: =AA32*AA41 -> 9561.2466 | AB40: =AB32*AB41 -> 10434.854 | AC40: =AC32*AC41 -> 12772.262 | AD40: =AD32*AD41 -> 47787.082 | AE40: =AE32*AE41 -> 55021.239 | AF40: =AF32*AF41 -> 75381.306 | AG40: =AG32*AG41 -> 114618.18 | AH40: =AH32*AH41 -> 139645.89 | AI40: =AI32*AI41 -> 188712.58
B41: As % of Payout | D41: 1 | E41: 1 | J41: 1 | K41: 1 | L41: 1 | M41: 1 | N41: 1 | O41: 1 | P41: 1 | Q41: =Q40/(Q37+Q40) -> 0.86413223 | R41: =R40/(R37+R40) -> 0.86165897 | S41: =S40/(S37+S40) -> 0.86428055 | T41: =-T40/T32 -> 0.89418697 | U41: =U40/(U37+U40) -> 0.86093018 | V41: =V40/(V37+V40) -> 0.84284037 | W41: =W40/(W37+W40) -> 0.81937322 | X41: =X40/(X37+X40) -> 0.68438083 | Y41: =-Y40/Y32 -> 0.81977474 | Z41: =Z40/(Z37+Z40) -> 0 | AA41: 0.8 | AB41: 0.8 | AC41: 0.8 | AD41: 0.8 | AE41: 0.8 | AF41: 0.8 | AG41: 0.8 | AH41: 0.8 | AI41: 0.8
A43: EBITDA | D43: =D17+'CFS - Estimates'!D9 -> 54921 | E43: =E17+'CFS - Estimates'!E9 -> 91155 | F43: =F17+'CFS - Estimates'!F9 -> 36022 | G43: =G17+'CFS - Estimates'!G9 -> 22639 | H43: =H17+'CFS - Estimates'!H9 -> 20532 | I43: =I17+'CFS - Estimates'!I9 -> 21960 | J43: =J17+'CFS - Estimates'!F9 -> 90770 | K43: =K17+'CFS - Estimates'!G9 -> 20601 | L43: =L17+'CFS - Estimates'!H9 -> 25235 | M43: =M17+'CFS - Estimates'!I9 -> 25143 | N43: =N17+'CFS - Estimates'!J9 -> 25260 | O43: =O17+'CFS - Estimates'!K9 -> 96239 | P43: =P17+'CFS - Estimates'!L9 -> 28885 | Q43: =Q17+'CFS - Estimates'!M9 -> 31133 | ... AI43: =AI17+'CFS - Estimates'!AE9 -> 484881.36
A44: EBITDA Margin | D44: =D43/D6 -> 0.30089247 | E44: =E43/E6 -> 0.35381176 | F44: =F43/F6 -> 0.52964962 | G44: =G43/G6 -> 0.32487623 | H44: =H43/H6 -> 0.29716899 | I44: =I43/I6 -> 0.28876499 | J44: =J43/J6 -> 0.32092803 | K44: =K43/K6 -> 0.29519825 | ... AI44: =AI43/AI6 -> 0.45404792

Sheet BS
K1: Hardcode | S1: Hardcode
K2: Formula | S2: Formula
S3: Assumption
D4: =IF(D7=D40,"OK",D7-D40) -> OK | E4: =IF(E7=E40,"OK",E7-E40) -> OK | F4: =IF(F7=F40,"OK",F7-F40) -> OK | G4: =IF(G7=G40,"OK",G7-G40) -> OK | H4: =IF(H7=H40,"OK",H7-H40) -> OK | I4: =IF(I7=I40,"OK",I7-I40) -> OK | J4: =IF(J7=J40,"OK",J7-J40) -> OK | K4: =IF(K7=K40,"OK",K7-K40) -> OK | ... AE4: =IF(AE7=AE40,"OK",AE7-AE40) -> OK
A5: Balance Sheet (Mn USD) | D5: 2020 | E5: 2021 | F5: 2022 | G5: 1Q23 | H5: 1Q23 | I5: 1Q23 | J5: 1Q23 | K5: 2023 | L5: 1Q24 | M5: 2Q24 | N5: 3Q24 | O5: 4Q24 | P5: 2024 | Q5: 1Q25 | R5: 1Q25 | S5: 1Q25 | T5: 1Q25 | U5: 2025 | V5: 1Q26 | W5: 2Q26 | X5: 3Q26 | Y5: 4Q26 | Z5: 2026 | AA5: 2027 | AB5: 2028 | AC5: 2029 | AD5: 2030 | AE5: 2031
A7: Assets | D7: =D9+D14 -> 319616 | E7: =E9+E14 -> 359268 | F7: =F9+F14 -> 365264 | G7: =G9+G14 -> 369491 | H7: =H9+H14 -> 383044 | I7: =I9+I14 -> 396711 | J7: =J9+J14 -> 402392 | K7: =K9+K14 -> 402392 | ... AE7: =AE9+AE14 -> 1837821.8
A9: Current Assets | D9: =D10+D11+D12 -> 174296 | E9: =E10+E11+E12 -> 188143 | F9: =F10+F11+F12 -> 164795 | G9: =G10+G11+G12 -> 161985 | H9: =H10+H11+H12 -> 168788 | I9: =I10+I11+I12 -> 176310 | J9: =J10+J11+J12 -> 171530 | K9: =K10+K11+K12 -> 171530 | ... V9: =V10+V11+V12 -> 213753 | W9: =SUM(W10:W12) -> 286540.59 | X9: =SUM(X10:X12) -> 290989.95 | Y9: =SUM(Y10:Y12) -> 286778.25 | Z9: =SUM(Z10:Z12) -> 286778.25 | AA9: =SUM(AA10:AA12) -> 224340.92 | AB9: =SUM(AB10:AB12) -> 192665.62 | AC9: =SUM(AC10:AC12) -> 172138.61 | AD9: =SUM(AD10:AD12) -> 223380.23 | AE9: =SUM(AE10:AE12) -> 282418.6
A10: Cash and cash equivalents | D10: 136694 | E10: 139649 | F10: 113762 | G10: ='Q - BS'!C9 -> 115102 | H10: ='Q - BS'!D9 -> 118332 | I10: ='Q - BS'!E9 -> 119935 | J10: ='Q - BS'!F9 -> 110916 | K10: 110916 | L10: ='Q - BS'!G9 -> 108090 | M10: ='Q - BS'!H9 -> 100725 | N10: ='Q - BS'!I9 -> 93230 | O10: ='Q - BS'!J9 -> 95657 | P10: 95657 | Q10: ='Q - BS'!K9 -> 95328 | R10: ='Q - BS'!L9 -> 95148 | S10: ='Q - BS'!M9 -> 98496 | T10: ='Q - BS'!N9 -> 126843 | U10: 126843 | V10: ='Q - BS'!O9 -> 126840 | W10: ='CFS - Estimates'!W33 -> 200340.67 | X10: ='CFS - Estimates'!X33 -> 193738.29 | Y10: ='CFS - Estimates'!Y33 -> 176128.91 | Z10: ='CFS - Estimates'!Z33 -> 176128.91 | AA10: ='CFS - Estimates'!AA33 -> 110213.21 | AB10: ='CFS - Estimates'!AB33 -> 57465.5 | AC10: ='CFS - Estimates'!AC33 -> 16898.453 | AD10: ='CFS - Estimates'!AD33 -> 48646.356 | AE10: ='CFS - Estimates'!AE33 -> 89855.563
A11: Accounts receivable | D11: 30930 | E11: 39304 | F11: 40258 | G11: ='Q - BS'!C10 -> 36036 | H11: ='Q - BS'!D10 -> 38804 | I11: ='Q - BS'!E10 -> 41020 | J11: ='Q - BS'!F10 -> 47964 | K11: 47964 | L11: ='Q - BS'!G10 -> 44552 | M11: ='Q - BS'!H10 -> 47087 | N11: ='Q - BS'!I10 -> 49104 | O11: ='Q - BS'!J10 -> 52340 | P11: 52340 | Q11: ='Q - BS'!K10 -> 51000 | R11: ='Q - BS'!L10 -> 55048 | S11: ='Q - BS'!M10 -> 57148 | T11: ='Q - BS'!N10 -> 62886 | U11: 62886 | V11: ='Q - BS'!O10 -> 62999 | W11: =W50 -> 66732.58 | X11: =X50 -> 75288.394 | Y11: =Y50 -> 85660.347 | Z11: =Z50 -> 85660.347 | AA11: =AA50 -> 88353.171 | AB11: =AB50 -> 104666.6 | AC11: =AC50 -> 120180.8 | AD11: =AD50 -> 135272.07 | AE11: =AE50 -> 149074.71
A12: Other current assets | D12: 6672 | E12: 9190 | F12: 10775 | G12: ='Q - BS'!C11 -> 10847 | H12: ='Q - BS'!D11 -> 11652 | I12: ='Q - BS'!E11 -> 15355 | J12: ='Q - BS'!F11 -> 12650 | K12: 12650 | L12: ='Q - BS'!G11 -> 12829 | M12: ='Q - BS'!H11 -> 14183 | N12: ='Q - BS'!I11 -> 15207 | O12: ='Q - BS'!J11 -> 15714 | P12: 15714 | Q12: ='Q - BS'!K11 -> 15724 | R12: ='Q - BS'!L11 -> 16020 | S12: ='Q - BS'!M11 -> 18303 | T12: ='Q - BS'!N11 -> 16309 | U12: 16309 | V12: ='Q - BS'!O11 -> 23914 | W12: =W53 -> 19467.345 | X12: =X53 -> 21963.262 | Y12: =Y53 -> 24988.986 | Z12: =Z53 -> 24988.986 | AA12: =AA53 -> 25774.542 | AB12: =AB53 -> 30533.523 | AC12: =AC53 -> 35059.354 | AD12: =AD53 -> 39461.804 | AE12: =AE53 -> 43488.334
A14: Non Current Assets | D14: =D15+D16+D17+D18+D19 -> 145320 | E14: =E15+E16+E17+E18+E19 -> 171125 | F14: =F15+F16+F17+F18+F19 -> 200469 | G14: =SUM(G15:G19) -> 207506 | H14: =SUM(H15:H19) -> 214256 | I14: =SUM(I15:I19) -> 220401 | J14: =SUM(J15:J19) -> 230862 | K14: =K15+K16+K17+K18+K19 -> 230862 | L14: =SUM(L15:L19) -> 241879 | M14: =SUM(M15:M19) -> 252775 | N14: =SUM(N15:N19) -> 272725 | O14: =SUM(O15:O19) -> 286545 | P14: =P15+P16+P17+P18+P19 -> 286545 | Q14: =SUM(Q15:Q19) -> 313322 | R14: =SUM(R15:R19) -> 335837 | S14: =SUM(S15:S19) -> 362522 | T14: =SUM(T15:T19) -> 389243 | U14: =U15+U16+U17+U18+U19 -> 389243 | V14: =SUM(V15:V19) -> 490166 | W14: =SUM(W15:W19) -> 528409.51 | X14: =SUM(X15:X19) -> 575601.24 | Y14: =SUM(Y15:Y19) -> 641566.93 | Z14: =SUM(Z15:Z19) -> 641566.93 | AA14: =SUM(AA15:AA19) -> 863090.54 | AB14: =SUM(AB15:AB19) -> 1088026.7 | AC14: =SUM(AC15:AC19) -> 1303257.7 | ... AE14: =SUM(AE15:AE19) -> 1555403.2
A15: Investiments | D15: 20703 | E15: 29549 | F15: 30492 | G15: ='Q - BS'!C14 -> 31213 | H15: ='Q - BS'!D14 -> 31224 | I15: ='Q - BS'!E14 -> 30907 | J15: ='Q - BS'!F14 -> 31008 | K15: 31008 | L15: ='Q - BS'!G14 -> 33994 | M15: ='Q - BS'!H14 -> 34172 | N15: ='Q - BS'!I14 -> 36177 | O15: ='Q - BS'!J14 -> 37982 | P15: 37982 | Q15: ='Q - BS'!K14 -> 51029 | R15: ='Q - BS'!L14 -> 52574 | S15: ='Q - BS'!M14 -> 63800 | T15: ='Q - BS'!N14 -> 68687 | U15: 68687 | V15: ='Q - BS'!O14 -> 106946 | W15: =V15 -> 106946 | X15: =W15 -> 106946 | Y15: =X15 -> 106946 | Z15: =Y15 -> 106946 | AA15: =Z15 -> 106946 | AB15: =AA15 -> 106946 | AC15: =AB15 -> 106946 | AD15: =AC15 -> 106946 | AE15: =AD15 -> 106946
A16: PP&E | D16: 84749 | E16: 97599 | F16: 112668 | G16: ='Q - BS'!C15 -> 117560 | H16: ='Q - BS'!D15 -> 121208 | I16: ='Q - BS'!E15 -> 125705 | J16: ='Q - BS'!F15 -> 134345 | K16: 134345 | L16: ='Q - BS'!G15 -> 143182 | M16: ='Q - BS'!H15 -> 151155 | N16: ='Q - BS'!I15 -> 161270 | O16: ='Q - BS'!J15 -> 171036 | P16: 171036 | Q16: ='Q - BS'!K15 -> 185062 | R16: ='Q - BS'!L15 -> 203231 | S16: ='Q - BS'!M15 -> 223787 | T16: ='Q - BS'!N15 -> 246597 | U16: 246597 | V16: ='Q - BS'!O15 -> 281020 | W16: =V16-'CFS - Estimates'!W17-'CFS - Estimates'!W9 -> 319263.51 | X16: =W16-'CFS - Estimates'!X17-'CFS - Estimates'!X9 -> 366455.24 | Y16: =X16-'CFS - Estimates'!Y17-'CFS - Estimates'!Y9 -> 432420.93 | Z16: =Y16 -> 432420.93 | AA16: =Z16-'CFS - Estimates'!AA17-'CFS - Estimates'!AA9 -> 653944.54 | AB16: =AA16-'CFS - Estimates'!AB17-'CFS - Estimates'!AB9 -> 878880.65 | AC16: =AB16-'CFS - Estimates'!AC17-'CFS - Estimates'!AC9 -> 1094111.7 | AD16: =AC16-'CFS - Estimates'!AD17-'CFS - Estimates'!AD9 -> 1239466.5 | AE16: =AD16-'CFS - Estimates'!AE17-'CFS - Estimates'!AE9 -> 1346257.2
A17: Lease | D17: 12211 | E17: 12959 | F17: 14381 | G17: ='Q - BS'!C16 -> 14447 | H17: ='Q - BS'!D16 -> 14469 | I17: ='Q - BS'!E16 -> 14199 | J17: ='Q - BS'!F16 -> 14091 | K17: 14091 | L17: ='Q - BS'!G16 -> 13768 | M17: ='Q - BS'!H16 -> 13606 | N17: ='Q - BS'!I16 -> 13561 | O17: ='Q - BS'!J16 -> 13588 | P17: 13588 | Q17: ='Q - BS'!K16 -> 13722 | R17: ='Q - BS'!L16 -> 14255 | S17: ='Q - BS'!M16 -> 14524 | T17: ='Q - BS'!N16 -> 15221 | U17: 15221 | V17: ='Q - BS'!O16 -> 15509 | W17: =V17 -> 15509 | X17: =W17 -> 15509 | Y17: =X17 -> 15509 | Z17: =Y17 -> 15509 | AA17: =Z17 -> 15509 | AB17: =AA17 -> 15509 | AC17: =AB17 -> 15509 | AD17: =AC17 -> 15509 | AE17: =AD17 -> 15509
A18: Goodwill | D18: 21175 | E18: 22956 | F18: 28960 | G18: ='Q - BS'!C17 -> 28994 | H18: ='Q - BS'!D17 -> 29210 | I18: ='Q - BS'!E17 -> 29146 | J18: ='Q - BS'!F17 -> 29198 | K18: 29198 | L18: ='Q - BS'!G17 -> 29183 | M18: ='Q - BS'!H17 -> 29185 | N18: ='Q - BS'!I17 -> 31935 | O18: ='Q - BS'!J17 -> 31885 | P18: 31885 | Q18: ='Q - BS'!K17 -> 32173 | R18: ='Q - BS'!L17 -> 32335 | S18: ='Q - BS'!M17 -> 33269 | T18: ='Q - BS'!N17 -> 33380 | U18: 33380 | V18: ='Q - BS'!O17 -> 57774 | W18: =V18 -> 57774 | X18: =W18 -> 57774 | Y18: =X18 -> 57774 | Z18: =Y18 -> 57774 | AA18: =Z18 -> 57774 | AB18: =AA18 -> 57774 | AC18: =AB18 -> 57774 | AD18: =AC18 -> 57774 | AE18: =AD18 -> 57774
A19: Others Non Current Assets | D19: 6482 | E19: 8062 | F19: 13968 | G19: ='Q - BS'!C18 -> 15292 | H19: ='Q - BS'!D18 -> 18145 | I19: ='Q - BS'!E18 -> 20444 | J19: ='Q - BS'!F18 -> 22220 | K19: 22220 | L19: ='Q - BS'!G18 -> 21752 | M19: ='Q - BS'!H18 -> 24657 | N19: ='Q - BS'!I18 -> 29782 | O19: ='Q - BS'!J18 -> 32054 | P19: 32054 | Q19: ='Q - BS'!K18 -> 31336 | R19: ='Q - BS'!L18 -> 33442 | S19: ='Q - BS'!M18 -> 27142 | T19: ='Q - BS'!N18 -> 25358 | U19: 25358 | V19: ='Q - BS'!O18 -> 28917 | W19: =V19 -> 28917 | X19: =W19 -> 28917 | Y19: =X19 -> 28917 | Z19: =Y19 -> 28917 | AA19: =Z19 -> 28917 | AB19: =AA19 -> 28917 | AC19: =AB19 -> 28917 | AD19: =AC19 -> 28917 | AE19: =AD19 -> 28917
A21: Liabilities | D21: =D23+D29 -> 97072 | E21: =E23+E29 -> 107633 | F21: =F23+F29 -> 109120 | G21: =G23+G29 -> 108597 | H21: =H23+H29 -> 115903 | I21: =I23+I29 -> 123509 | J21: =J23+J29 -> 119013 | K21: =K23+K29 -> 119013 | ... AE21: =AE23+AE29 -> 376721.27
A23: Current Liabilities | D23: =D24+D25+D26+D27 -> 56834 | E23: =E24+E25+E26+E27 -> 64254 | F23: =F24+F25+F26+F27 -> 69300 | G23: =G24+G25+G26+G27 -> 68854 | H23: =H24+H25+H26+H27 -> 77709 | I23: =I24+I25+I26+I27 -> 86295 | J23: =J24+J25+J26+J27 -> 81814 | K23: =K24+K25+K26+K27 -> 81814 | ... V23: =V24+V25+V26+V27 -> 111188 | W23: =SUM(W24:W27) -> 102309.29 | X23: =SUM(X24:X27) -> 115613.16 | Y23: =SUM(Y24:Y27) -> 131480.94 | Z23: =SUM(Z24:Z27) -> 131480.94 | AA23: =SUM(AA24:AA27) -> 135873.08 | AB23: =SUM(AB24:AB27) -> 158581.79 | AC23: =SUM(AC24:AC27) -> 179141.32 | AD23: =SUM(AD24:AD27) -> 200848.51 | AE23: =SUM(AE24:AE27) -> 220389.21
A24: Accounts Payable | D24: 5589 | E24: 6037 | F24: 5128 | G24: ='Q - BS'!C23 -> 4184 | H24: ='Q - BS'!D23 -> 5313 | I24: ='Q - BS'!E23 -> 5803 | J24: ='Q - BS'!F23 -> 7493 | K24: 7493 | L24: ='Q - BS'!G23 -> 6198 | M24: ='Q - BS'!H23 -> 6092 | N24: ='Q - BS'!I23 -> 7049 | O24: ='Q - BS'!J23 -> 7987 | P24: 7987 | Q24: ='Q - BS'!K23 -> 8497 | R24: ='Q - BS'!L23 -> 8347 | S24: ='Q - BS'!M23 -> 10546 | T24: ='Q - BS'!N23 -> 12200 | U24: 12200 | V24: ='Q - BS'!O23 -> 16852 | W24: =W64 -> 9264.8646 | X24: =X64 -> 10469.629 | Y24: =Y64 -> 11906.574 | Z24: =Z64 -> 11906.574 | AA24: =AA64 -> 12332.107 | AB24: =AB64 -> 14393.194 | AC24: =AC64 -> 16259.217 | AD24: =AD64 -> 18229.404 | AE24: =AE64 -> 20002.957
A25: Salary | D25: 11086 | E25: 13889 | F25: 14028 | G25: ='Q - BS'!C24 -> 9954 | H25: ='Q - BS'!D24 -> 11260 | I25: ='Q - BS'!E24 -> 12562 | J25: ='Q - BS'!F24 -> 15140 | K25: 15140 | L25: ='Q - BS'!G24 -> 9703 | M25: ='Q - BS'!H24 -> 11373 | N25: ='Q - BS'!I24 -> 12908 | O25: ='Q - BS'!J24 -> 15069 | P25: 15069 | Q25: ='Q - BS'!K24 -> 9984 | R25: ='Q - BS'!L24 -> 12168 | S25: ='Q - BS'!M24 -> 13944 | T25: ='Q - BS'!N24 -> 17546 | U25: 17546 | V25: ='Q - BS'!O24 -> 13947 | W25: =W58 -> 15832.395 | X25: =X58 -> 17891.173 | Y25: =Y58 -> 20346.718 | Z25: =Z58 -> 20346.718 | AA25: =AA58 -> 20766.995 | AB25: =AB58 -> 24237.819 | AC25: =AC58 -> 27380.16 | AD25: =AD58 -> 30697.911 | AE25: =AE58 -> 33684.534
A26: Accrued Revenue Share | D26: 7500 | E26: 8996 | F26: 8370 | G26: ='Q - BS'!C25 -> 7816 | H26: ='Q - BS'!D25 -> 7990 | I26: ='Q - BS'!E25 -> 8025 | J26: ='Q - BS'!F25 -> 8876 | K26: 8876 | L26: ='Q - BS'!G25 -> 8520 | M26: ='Q - BS'!H25 -> 8899 | N26: ='Q - BS'!I25 -> 9365 | O26: ='Q - BS'!J25 -> 9802 | P26: 9802 | Q26: ='Q - BS'!K25 -> 9965 | R26: ='Q - BS'!L25 -> 9787 | S26: ='Q - BS'!M25 -> 10081 | T26: ='Q - BS'!N25 -> 10864 | U26: 10864 | V26: ='Q - BS'!O25 -> 10208 | W26: =W61 -> 10951.218 | X26: =X61 -> 12375.268 | Y26: =Y61 -> 14073.761 | Z26: =Z61 -> 14073.761 | AA26: =AA61 -> 14576.748 | AB26: =AB61 -> 17012.985 | AC26: =AC61 -> 19218.654 | AD26: =AD61 -> 21547.447 | AE26: =AE61 -> 23643.814
A27: Other Current Liabilities | D27: 32659 | E27: 35332 | F27: 41774 | G27: ='Q - BS'!C26 -> 46900 | H27: ='Q - BS'!D26 -> 53146 | I27: ='Q - BS'!E26 -> 59905 | J27: ='Q - BS'!F26 -> 50305 | K27: 50305 | L27: ='Q - BS'!G26 -> 52576 | M27: ='Q - BS'!H26 -> 51549 | N27: ='Q - BS'!I26 -> 51481 | O27: ='Q - BS'!J26 -> 56264 | P27: 56264 | Q27: ='Q - BS'!K26 -> 63208 | R27: ='Q - BS'!L26 -> 57008 | S27: ='Q - BS'!M26 -> 64979 | T27: ='Q - BS'!N26 -> 62135 | U27: 62135 | V27: ='Q - BS'!O26 -> 70181 | W27: =W67 -> 66260.811 | X27: =X67 -> 74877.089 | Y27: =Y67 -> 85153.891 | Z27: =Z67 -> 85153.891 | AA27: =AA67 -> 88197.234 | AB27: =AB67 -> 102937.79 | AC27: =AC67 -> 116283.29 | AD27: =AD67 -> 130373.75 | AE27: =AE67 -> 143057.91
A29: Non Current Liabilities | D29: =D30+D31+D32+D33 -> 40238 | E29: =E30+E31+E32+E33 -> 43379 | F29: =F30+F31+F32+F33 -> 39820 | G29: =G30+G31+G32+G33 -> 39743 | H29: =H30+H31+H32+H33 -> 38194 | I29: =I30+I31+I32+I33 -> 37214 | J29: =J30+J31+J32+J33 -> 37199 | K29: =K30+K31+K32+K33 -> 37199 | ... V29: =V30+V31+V32+V33 -> 113985 | W29: =SUM(W30:W33) -> 117860.05 | X29: =SUM(X30:X33) -> 121928.85 | Y29: =SUM(Y30:Y33) -> 126201.1 | Z29: =SUM(Z30:Z33) -> 126201.1 | AA29: =SUM(AA30:AA33) -> 135172.8 | AB29: =SUM(AB30:AB33) -> 143067.91 | AC29: =SUM(AC30:AC33) -> 149462.94 | AD29: =SUM(AD30:AD33) -> 153982.1 | AE29: =SUM(AE30:AE33) -> 156332.06
A30: Long term Debt | D30: 13932 | E30: 14817 | F30: 14701 | G30: ='Q - BS'!C29 -> 13697 | H30: ='Q - BS'!D29 -> 13705 | I30: ='Q - BS'!E29 -> 13781 | J30: ='Q - BS'!F29 -> 13253 | K30: 13253 | L30: ='Q - BS'!G29 -> 13228 | M30: ='Q - BS'!H29 -> 13238 | N30: ='Q - BS'!I29 -> 12297 | O30: ='Q - BS'!J29 -> 10883 | P30: 10883 | Q30: ='Q - BS'!K29 -> 10886 | R30: ='Q - BS'!L29 -> 23607 | S30: ='Q - BS'!M29 -> 21607 | T30: ='Q - BS'!N29 -> 46547 | U30: 46547 | V30: ='Q - BS'!O29 -> 77501 | W30: ='Debt Schedule'!W12 -> 81376.05 | X30: ='Debt Schedule'!X12 -> 85444.853 | Y30: ='Debt Schedule'!Y12 -> 89717.095 | Z30: ='Debt Schedule'!Z12 -> 89717.095 | AA30: ='Debt Schedule'!AA12 -> 98688.805 | AB30: ='Debt Schedule'!AB12 -> 106583.91 | AC30: ='Debt Schedule'!AC12 -> 112978.94 | AD30: ='Debt Schedule'!AD12 -> 117498.1 | AE30: ='Debt Schedule'!AE12 -> 119848.06
A31: Lease | D31: 11146 | E31: 11389 | F31: 12501 | G31: ='Q - BS'!C30 -> 12799 | H31: ='Q - BS'!D30 -> 12746 | I31: ='Q - BS'!E30 -> 12550 | J31: ='Q - BS'!F30 -> 12460 | K31: 12460 | L31: ='Q - BS'!G30 -> 11957 | M31: ='Q - BS'!H30 -> 11708 | N31: ='Q - BS'!I30 -> 11654 | O31: ='Q - BS'!J30 -> 11691 | P31: 11691 | Q31: ='Q - BS'!K30 -> 11678 | R31: ='Q - BS'!L30 -> 11952 | S31: ='Q - BS'!M30 -> 12106 | T31: ='Q - BS'!N30 -> 12744 | U31: 12744 | V31: ='Q - BS'!O30 -> 12983 | W31: ='Debt Schedule'!W23 -> 12983 | X31: ='Debt Schedule'!X23 -> 12983 | Y31: ='Debt Schedule'!Y23 -> 12983 | Z31: ='Debt Schedule'!Z23 -> 12983 | AA31: ='Debt Schedule'!AA23 -> 12983 | AB31: ='Debt Schedule'!AB23 -> 12983 | AC31: ='Debt Schedule'!AC23 -> 12983 | AD31: ='Debt Schedule'!AD23 -> 12983 | AE31: ='Debt Schedule'!AE23 -> 12983
A32: Taxes | D32: 8849 | E32: 9176 | F32: 9258 | G32: ='Q - BS'!C31 -> 9722 | H32: ='Q - BS'!D31 -> 8753 | I32: ='Q - BS'!E31 -> 8038 | J32: ='Q - BS'!F31 -> 8474 | K32: 8474 | L32: ='Q - BS'!G31 -> 9234 | M32: ='Q - BS'!H31 -> 7703 | N32: ='Q - BS'!I31 -> 8219 | O32: ='Q - BS'!J31 -> 8782 | P32: 8782 | Q32: ='Q - BS'!K31 -> 9773 | R32: ='Q - BS'!L31 -> 10027 | S32: ='Q - BS'!M31 -> 10072 | T32: ='Q - BS'!N31 -> 9531 | U32: 9531 | V32: ='Q - BS'!O31 -> 12457 | W32: =V32 -> 12457 | X32: =W32 -> 12457 | Y32: =X32 -> 12457 | Z32: =Y32 -> 12457 | AA32: =Z32 -> 12457 | AB32: =AA32 -> 12457 | AC32: =AB32 -> 12457 | AD32: =AC32 -> 12457 | AE32: =AD32 -> 12457
A33: Other Non Current Liabilities | D33: 6311 | E33: 7997 | F33: 3360 | G33: ='Q - BS'!C32 -> 3525 | H33: ='Q - BS'!D32 -> 2990 | I33: ='Q - BS'!E32 -> 2845 | J33: ='Q - BS'!F32 -> 3012 | K33: 3012 | L33: ='Q - BS'!G32 -> 3090 | M33: ='Q - BS'!H32 -> 3455 | N33: ='Q - BS'!I32 -> 3174 | O33: ='Q - BS'!J32 -> 4694 | P33: 4694 | Q33: ='Q - BS'!K32 -> 6116 | R33: ='Q - BS'!L32 -> 6241 | S33: ='Q - BS'!M32 -> 6267 | T33: ='Q - BS'!N32 -> 8449 | U33: 8449 | V33: ='Q - BS'!O32 -> 11044 | W33: =V33 -> 11044 | X33: =W33 -> 11044 | Y33: =X33 -> 11044 | Z33: =Y33 -> 11044 | AA33: =Z33 -> 11044 | AB33: =AA33 -> 11044 | AC33: =AB33 -> 11044 | AD33: =AC33 -> 11044 | AE33: =AD33 -> 11044
A35: Equity | D35: =D36+D37 -> 222544 | E35: =E36+E37 -> 251635 | F35: =F36+F37 -> 256144 | G35: =G36+G37 -> 260894 | H35: =H36+H37 -> 267141 | I35: =I36+I37 -> 273202 | J35: =J36+J37 -> 283379 | K35: =K36+K37 -> 283379 | ... V35: =V36+V37 -> 478746 | W35: =SUM(W36:W38) -> 594780.76 | X35: =SUM(X36:X38) -> 629049.18 | Y35: =SUM(Y36:Y38) -> 670663.14 | Z35: =SUM(Z36:Z38) -> 670663.14 | AA35: =SUM(AA36:AA38) -> 816385.57 | AB35: =SUM(AB36:AB38) -> 979042.57 | AC35: =SUM(AC36:AC38) -> 1146792.1 | AD35: =SUM(AD36:AD38) -> 1317162.1 | AE35: =SUM(AE36:AE38) -> 1461100.6
A36: Share Capital | D36: 58510 | E36: 61774 | F36: 68184 | G36: ='Q - BS'!C35 -> 70269 | H36: ='Q - BS'!D35 -> 72248 | I36: ='Q - BS'!E35 -> 74591 | J36: ='Q - BS'!F35 -> 76534 | K36: 76534 | L36: ='Q - BS'!G35 -> 77913 | M36: ='Q - BS'!H35 -> 79732 | N36: ='Q - BS'!I35 -> 82030 | O36: ='Q - BS'!J35 -> 84800 | P36: 84800 | Q36: ='Q - BS'!K35 -> 86725 | R36: ='Q - BS'!L35 -> 89283 | S36: ='Q - BS'!M35 -> 91695 | T36: ='Q - BS'!N35 -> 93126 | U36: 93126 | V36: ='Q - BS'!O35 -> 96902 | W36: =V36+84750 -> 181652 | X36: =W36 -> 181652 | Y36: =X36 -> 181652 | Z36: =Y36 -> 181652 | AA36: =Z36 -> 181652 | AB36: =AA36 -> 181652 | AC36: =AB36 -> 181652 | AD36: =AC36 -> 181652 | AE36: =AD36 -> 181652
A37: Income Reserves | D37: 164034 | E37: 189861 | F37: 187960 | G37: ='Q - BS'!C36 -> 190625 | H37: ='Q - BS'!D36 -> 194893 | I37: ='Q - BS'!E36 -> 198611 | J37: ='Q - BS'!F36 -> 206845 | K37: 206845 | L37: ='Q - BS'!G36 -> 214931 | M37: ='Q - BS'!H36 -> 221021 | N37: ='Q - BS'!I36 -> 232089 | O37: ='Q - BS'!J36 -> 240284 | P37: 240284 | Q37: ='Q - BS'!K36 -> 258542 | R37: ='Q - BS'!L36 -> 273633 | S37: ='Q - BS'!M36 -> 295172 | T37: ='Q - BS'!N36 -> 322139 | U37: 322139 | V37: ='Q - BS'!O36 -> 381844 | W37: =V37+'Income Statement'!AA35 -> 409730.97 | X37: =W37+'Income Statement'!AB35 -> 440165.96 | Y37: =X37+'Income Statement'!AC35 -> 477418.39 | Z37: =Y37 -> 477418.39 | AA37: =Z37+'Income Statement'!AE35 -> 605146.27 | AB37: =AA37+'Income Statement'!AF35 -> 746486.21 | AC37: =AB37+'Income Statement'!AG35 -> 889758.93 | AD37: =AC37+'Income Statement'!AH35 -> 1032578.6 | AE37: =AD37+'Income Statement'!AI35 -> 1146155.6 | AG37: =BS!Z30+BS!Z31-BS!Y30-BS!Y31 -> 0
A38: SBC | W38: ='CFS - Estimates'!W11+'CFS - Estimates'!W25 -> 3397.7932 | X38: =W38+'CFS - Estimates'!X11+'CFS - Estimates'!X25 -> 7231.219 | Y38: =X38+'CFS - Estimates'!Y11+'CFS - Estimates'!Y25 -> 11592.749 | Z38: =Y38 -> 11592.749 | AA38: =Z38+'CFS - Estimates'!AA11+'CFS - Estimates'!AA25 -> 29587.306 | AB38: =AA38+'CFS - Estimates'!AB11+'CFS - Estimates'!AB25 -> 50904.357 | AC38: =AB38+'CFS - Estimates'!AC11+'CFS - Estimates'!AC25 -> 75381.128 | AD38: =AC38+'CFS - Estimates'!AD11+'CFS - Estimates'!AD25 -> 102931.48 | AE38: =AD38+'CFS - Estimates'!AE11+'CFS - Estimates'!AE25 -> 133292.96
A40: Liabilities+Equity | D40: =D35+D21 -> 319616 | E40: =E35+E21 -> 359268 | F40: =F35+F21 -> 365264 | G40: =G35+G21 -> 369491 | H40: =H35+H21 -> 383044 | I40: =I35+I21 -> 396711 | J40: =J35+J21 -> 402392 | K40: =K35+K21 -> 402392 | ... AE40: =AE35+AE21 -> 1837821.8
A42: OWC | D42: =D11+D12-D24-D25-D26-D27 -> -19232 | E42: =E11+E12-E24-E25-E26-E27 -> -15760 | F42: =F11+F12-F24-F25-F26-F27 -> -18267 | G42: ='Q - BS'!C40 -> -21971 | H42: ='Q - BS'!D40 -> -27253 | I42: ='Q - BS'!E40 -> -29920 | J42: ='Q - BS'!F40 -> -21200 | K42: =K11+K12-K24-K25-K26-K27 -> -21200 | L42: ='Q - BS'!G40 -> -19616 | M42: ='Q - BS'!H40 -> -16643 | N42: ='Q - BS'!I40 -> -16492 | O42: ='Q - BS'!J40 -> -21068 | P42: =P11+P12-P24-P25-P26-P27 -> -21068 | Q42: =Q11+Q12-Q24-Q25-Q26-Q27 -> -24930 | R42: =R11+R12-R24-R25-R26-R27 -> -16242 | S42: =S11+S12-S24-S25-S26-S27 -> -24099 | T42: =T11+T12-T24-T25-T26-T27 -> -23550 | U42: =U11+U12-U24-U25-U26-U27 -> -23550 | V42: =V11+V12-V24-V25-V26-V27 -> -24275 | W42: =W50+W53-W58-W61-W64-W67 -> -16109.364 | X42: =X50+X53-X58-X61-X64-X67 -> -18361.503 | Y42: =Y50+Y53-Y58-Y61-Y64-Y67 -> -20831.611 | Z42: =Z50+Z53-Z58-Z61-Z64-Z67 -> -20831.611 | AA42: =AA50+AA53-AA58-AA61-AA64-AA67 -> -21745.371 | AB42: =AB50+AB53-AB58-AB61-AB64-AB67 -> -23381.672 | AC42: =AC50+AC53-AC58-AC61-AC64-AC67 -> -23901.159 | AD42: =AD50+AD53-AD58-AD61-AD64-AD67 -> -26114.637 | AE42: =AE50+AE53-AE58-AE61-AE64-AE67 -> -27826.17
A43: Δ OWC | E43: =E42-D42 -> 3472 | F43: =F42-E42 -> -2507 | G43: ='Q - BS'!C41 -> -3704 | H43: ='Q - BS'!D41 -> -5282 | I43: ='Q - BS'!E41 -> -2667 | J43: ='Q - BS'!F41 -> 8720 | K43: =K42-F42 -> -2933 | L43: ='Q - BS'!G41 -> 1584 | M43: ='Q - BS'!H41 -> 2973 | N43: ='Q - BS'!I41 -> 151 | O43: ='Q - BS'!J41 -> -4576 | P43: =P42-K42 -> 132 | Q43: ='Q - BS'!K41 -> -3862 | R43: ='Q - BS'!L41 -> 8688 | S43: ='Q - BS'!M41 -> -7857 | T43: ='Q - BS'!N41 -> 549 | U43: =U42-P42 -> -2482 | V43: ='Q - BS'!O41 -> -725 | W43: =W42-V42 -> 8165.6362 | X43: =X42-W42 -> -2252.1392 | Y43: =Y42-X42 -> -2470.1081 | Z43: =SUM(V43:Y43) -> 2718.389 | AA43: =AA42-Z42 -> -913.76001 | AB43: =AB42-AA42 -> -1636.3012 | AC43: =AC42-AB42 -> -519.48722 | AD43: =AD42-AC42 -> -2213.4781 | AE43: =AE42-AD42 -> -1711.5321
A45: Revenue | D45: ='Income Statement'!D6 -> 182527 | E45: ='Income Statement'!E6 -> 257637 | F45: ='Income Statement'!J6 -> 282836 | G45: ='Income Statement'!K6 -> 69787 | H45: ='Income Statement'!L6 -> 74604 | I45: ='Income Statement'!M6 -> 76693 | J45: ='Income Statement'!N6 -> 86310 | K45: ='Income Statement'!O6 -> 307394 | L45: ='Income Statement'!P6 -> 80539 | M45: ='Income Statement'!Q6 -> 84742 | ... AE45: ='Income Statement'!AI6 -> 1067907.9
A46: COGS | D46: ='Income Statement'!D8 -> 84732 | E46: ='Income Statement'!E8 -> 110939 | F46: ='Income Statement'!J8 -> 126203 | G46: ='Income Statement'!K8 -> 30612 | H46: ='Income Statement'!L8 -> 31916 | I46: ='Income Statement'!M8 -> 33229 | J46: ='Income Statement'!N8 -> 37575 | K46: ='Income Statement'!O8 -> 133332 | L46: ='Income Statement'!P8 -> 33712 | M46: ='Income Statement'!Q8 -> 35507 | ... AE46: ='Income Statement'!AI8 -> 374216.09
A47: SG&A | D47: ='Income Statement'!D12 -> 56571 | E47: ='Income Statement'!E12 -> 67984 | F47: ='Income Statement'!J12 -> 81791 | G47: ='Income Statement'!K12 -> 21760 | H47: ='Income Statement'!L12 -> 20850 | I47: ='Income Statement'!M12 -> 22121 | J47: ='Income Statement'!N12 -> 25038 | K47: ='Income Statement'!O12 -> 89769 | L47: ='Income Statement'!P12 -> 21355 | M47: ='Income Statement'!Q12 -> 21810 | ... AE47: ='Income Statement'!AI12 -> 258387.3
A48: Days | D48: =IF(ISNUMBER(D5),360,90) -> 360 | E48: =IF(ISNUMBER(E5),360,90) -> 360 | F48: =IF(ISNUMBER(F5),360,90) -> 360 | G48: =IF(ISNUMBER(G5),360,90) -> 90 | H48: =IF(ISNUMBER(H5),360,90) -> 90 | I48: =IF(ISNUMBER(I5),360,90) -> 90 | J48: =IF(ISNUMBER(J5),360,90) -> 90 | K48: =IF(ISNUMBER(K5),360,90) -> 360 | ... AE48: =IF(ISNUMBER(AE5),360,90) -> 360
A49: Current Assets
A50: Accounts Receivible | D50: =D11 -> 30930 | E50: =E11 -> 39304 | F50: =F11 -> 40258 | G50: =G11 -> 36036 | H50: =H11 -> 38804 | I50: =I11 -> 41020 | J50: =J11 -> 47964 | K50: =K11 -> 47964 | ... V50: =V11 -> 62999 | W50: =W51*W$45/W48 -> 66732.58 | X50: =X51*X$45/X48 -> 75288.394 | Y50: =Y51*Y$45/Y48 -> 85660.347 | Z50: =Y50 -> 85660.347 | AA50: =AA51*AA$45/AA48 -> 88353.171 | AB50: =AB51*AB$45/AB48 -> 104666.6 | AC50: =AC51*AC$45/AC48 -> 120180.8 | AD50: =AD51*AD$45/AD48 -> 135272.07 | AE50: =AE51*AE$45/AE48 -> 149074.71
...

Sheet Comps
E1: Hardcode
E2: Formula
E3: Assumption
B5: COMPARABLE COMPANY ANALYSIS | S5: Tabela Auxiliar
B6: Trading Multiples | F6: P/E | J6: EV/SALES | N6: EV/EBITDA | S6: {=F9:H15} -> 19.01 | T6: 17.82 | U6: 15.19 | W6: {=J9:L15} -> 6.2 | X6: 5.17 | Y6: 4.4 | AA6: {=N9:P15} -> 10.99 | AB6: 9.01 | AC6: 7.31
S7: 27.29 | T7: 23.58 | U7: 18.43 | W7: 3.2 | X7: 2.83 | Y7: 2.48 | AA7: 12.41 | AB7: 9.76 | AC7: 7.7
C8: Company | F8: FY26 | G8: FY27 | H8: FY28 | J8: FY26 | K8: FY27 | L8: FY28 | N8: FY26 | O8: FY27 | P8: FY28 | S8: 7.01 | T8: 5.91 | U8: 4.86 | W8: 1.23 | X8: 1.12 | Y8: 1.03 | AA8: 6.55 | AB8: 5.28 | AC8: 4.85
C9: Meta Platforms | F9: ='Multiplos base'!O8 -> 19.01 | G9: ='Multiplos base'!P8 -> 17.82 | H9: ='Multiplos base'!Q8 -> 15.19 | J9: ='Multiplos base'!K8 -> 6.2 | K9: ='Multiplos base'!L8 -> 5.17 | L9: ='Multiplos base'!M8 -> 4.4 | N9: ='Multiplos base'!G8 -> 10.99 | O9: ='Multiplos base'!H8 -> 9.01 | P9: ='Multiplos base'!I8 -> 7.31 | S9: 19.1 | T9: 17.92 | U9: 14.97 | W9: 5.67 | X9: 5.09 | Y9: 4.62 | AA9: 17 | AB9: 14.44 | AC9: 12.49
C10: Amazon.com | F10: ='Multiplos base'!O9 -> 27.29 | G10: ='Multiplos base'!P9 -> 23.58 | H10: ='Multiplos base'!Q9 -> 18.43 | J10: ='Multiplos base'!K9 -> 3.2 | K10: ='Multiplos base'!L9 -> 2.83 | L10: ='Multiplos base'!M9 -> 2.48 | N10: ='Multiplos base'!G9 -> 12.41 | O10: ='Multiplos base'!H9 -> 9.76 | P10: ='Multiplos base'!I9 -> 7.7 | S10: 18.15 | T10: 16.61 | U10: 14.87 | W10: 4.29 | X10: 4.07 | Y10: 3.88 | AA10: 14.09 | AB10: 13 | AC10: 12.01
C11: Snap | F11: ='Multiplos base'!O10 -> 7.01 | G11: ='Multiplos base'!P10 -> 5.91 | H11: ='Multiplos base'!Q10 -> 4.86 | J11: ='Multiplos base'!K10 -> 1.23 | K11: ='Multiplos base'!L10 -> 1.12 | L11: ='Multiplos base'!M10 -> 1.03 | N11: ='Multiplos base'!G10 -> 6.55 | O11: ='Multiplos base'!H10 -> 5.28 | P11: ='Multiplos base'!I10 -> 4.85 | S11: 23.14 | T11: 20.09 | U11: 17.09 | W11: 8.88 | X11: 7.61 | Y11: 6.41 | AA11: 14.79 | AB11: 12.3 | AC11: 9.98
C12: Netflix | F12: ='Multiplos base'!O11 -> 19.1 | G12: ='Multiplos base'!P11 -> 17.92 | H12: ='Multiplos base'!Q11 -> 14.97 | J12: ='Multiplos base'!K11 -> 5.67 | K12: ='Multiplos base'!L11 -> 5.09 | L12: ='Multiplos base'!M11 -> 4.62 | N12: ='Multiplos base'!G11 -> 17 | O12: ='Multiplos base'!H11 -> 14.44 | P12: ='Multiplos base'!I11 -> 12.49 | S12: 36.99 | T12: 33.33 | U12: 29.98 | W12: 10.05 | X12: 9.18 | Y12: 8.57 | AA12: 28.33 | AB12: 26.06 | AC12: 23.81
C13: eBay | F13: ='Multiplos base'!O12 -> 18.15 | G13: ='Multiplos base'!P12 -> 16.61 | H13: ='Multiplos base'!Q12 -> 14.87 | J13: ='Multiplos base'!K12 -> 4.29 | K13: ='Multiplos base'!L12 -> 4.07 | L13: ='Multiplos base'!M12 -> 3.88 | N13: ='Multiplos base'!G12 -> 14.09 | O13: ='Multiplos base'!H12 -> 13 | P13: ='Multiplos base'!I12 -> 12.01
C14: Microsoft | F14: ='Multiplos base'!O13 -> 23.14 | G14: ='Multiplos base'!P13 -> 20.09 | H14: ='Multiplos base'!Q13 -> 17.09 | J14: ='Multiplos base'!K13 -> 8.88 | K14: ='Multiplos base'!L13 -> 7.61 | L14: ='Multiplos base'!M13 -> 6.41 | N14: ='Multiplos base'!G13 -> 14.79 | O14: ='Multiplos base'!H13 -> 12.3 | P14: ='Multiplos base'!I13 -> 9.98
C15: Apple | F15: ='Multiplos base'!O14 -> 36.99 | G15: ='Multiplos base'!P14 -> 33.33 | H15: ='Multiplos base'!Q14 -> 29.98 | J15: ='Multiplos base'!K14 -> 10.05 | K15: ='Multiplos base'!L14 -> 9.18 | L15: ='Multiplos base'!M14 -> 8.57 | N15: ='Multiplos base'!G14 -> 28.33 | O15: ='Multiplos base'!H14 -> 26.06 | P15: ='Multiplos base'!I14 -> 23.81
B19: TRADING MULTIPLES STATISTICS
G20: P/E | K20: EV/SALES | O20: EV/EBITDA
G21: FY26 | H21: FY27 | I21: FY28 | K21: FY26 | L21: FY27 | M21: FY28 | O21: FY26 | P21: FY27 | Q21: FY28
C22: Minimum | G22: =MIN(F9:F15) -> 7.01 | H22: =MIN(G9:G15) -> 5.91 | I22: =MIN(H9:H15) -> 4.86 | K22: =MIN(J9:J15) -> 1.23 | L22: =MIN(K9:K15) -> 1.12 | M22: =MIN(L9:L15) -> 1.03 | O22: =MIN(N9:N15) -> 6.55 | P22: =MIN(O9:O15) -> 5.28 | Q22: =MIN(P9:P15) -> 4.85 | T22: Implied Share Price
C23: Valuation | G23: =G22*G$50 -> 1395781 | H23: =H22*H$50 -> 1161341.1 | I23: =I22*I$50 -> 1144853.6 | K23: =K22*K$50-K$52 -> 850461.36 | L23: =L22*L$50-L$52 -> 922628.54 | M23: =M22*M$50-M$52 -> 986033.65 | O23: =O22*O$50-O$52 -> 1672061.8 | P23: =P22*P$50-P$52 -> 1651009.4 | Q23: =Q22*Q$50-Q$52 -> 1811036.9 | T23: Metric | V23: Share Price
T24: Minimum
